<?xml version="1.0" encoding="UTF-8"?>
<!-- Generated by org.testng.reporters.JUnitReportReporter -->
<testsuite hostname="HIH-D-1894" name="com.netease.vstore.test.cancelorder.CancelUnshipedOrder" tests="7" failures="1" timestamp="30 Jun 2015 03:19:23 GMT" time="31.046" errors="0">
  <testcase name="xiupinLoginTest" time="9.619" classname="com.netease.vstore.test.cancelorder.CancelUnshipedOrder"/>
  <testcase name="cancelUnpaidOrderTest" time="13.640" classname="com.netease.vstore.test.cancelorder.CancelUnshipedOrder">
    <failure type="java.lang.AssertionError" message="expected [true] but found [false]">
      <![CDATA[java.lang.AssertionError: expected [true] but found [false]
	at org.testng.Assert.fail(Assert.java:94)
	at org.testng.Assert.failNotEquals(Assert.java:496)
	at org.testng.Assert.assertTrue(Assert.java:42)
	at org.testng.Assert.assertTrue(Assert.java:52)
	at com.netease.vstore.Order.cancelUnpaidOrder(Order.java:334)
	at com.netease.vstore.test.cancelorder.CancelUnshipedOrder.cancelUnpaidOrderTest(CancelUnshipedOrder.java:86)
	at sun.reflect.NativeMethodAccessorImpl.invoke0(Native Method)
	at sun.reflect.NativeMethodAccessorImpl.invoke(Unknown Source)
	at sun.reflect.DelegatingMethodAccessorImpl.invoke(Unknown Source)
	at java.lang.reflect.Method.invoke(Unknown Source)
	at org.testng.internal.MethodInvocationHelper.invokeMethod(MethodInvocationHelper.java:85)
	at org.testng.internal.Invoker.invokeMethod(Invoker.java:659)
	at org.testng.internal.Invoker.invokeTestMethod(Invoker.java:845)
	at org.testng.internal.Invoker.invokeTestMethods(Invoker.java:1153)
	at org.testng.internal.TestMethodWorker.invokeTestMethods(TestMethodWorker.java:125)
	at org.testng.internal.TestMethodWorker.run(TestMethodWorker.java:108)
	at org.testng.TestRunner.privateRun(TestRunner.java:771)
	at org.testng.TestRunner.run(TestRunner.java:621)
	at org.testng.SuiteRunner.runTest(SuiteRunner.java:357)
	at org.testng.SuiteRunner.runSequentially(SuiteRunner.java:352)
	at org.testng.SuiteRunner.privateRun(SuiteRunner.java:310)
	at org.testng.SuiteRunner.run(SuiteRunner.java:259)
	at org.testng.SuiteRunnerWorker.runSuite(SuiteRunnerWorker.java:52)
	at org.testng.SuiteRunnerWorker.run(SuiteRunnerWorker.java:86)
	at org.testng.TestNG.runSuitesSequentially(TestNG.java:1199)
	at org.testng.TestNG.runSuitesLocally(TestNG.java:1124)
	at org.testng.TestNG.run(TestNG.java:1032)
	at org.testng.remote.RemoteTestNG.run(RemoteTestNG.java:111)
	at org.testng.remote.RemoteTestNG.initAndRun(RemoteTestNG.java:204)
	at org.testng.remote.RemoteTestNG.main(RemoteTestNG.java:175)
]]>
    </failure>
  </testcase> <!-- cancelUnpaidOrderTest -->
  <testcase name="LogoutTest" time="2.643" classname="com.netease.vstore.test.cancelorder.CancelUnshipedOrder"/>
  <testcase name="pofileIndexTest" time="1.196" classname="com.netease.vstore.test.cancelorder.CancelUnshipedOrder"/>
  <testcase name="ToBeShippedOrder" time="0.574" classname="com.netease.vstore.test.cancelorder.CancelUnshipedOrder"/>
  <testcase name="myOrderTest" time="1.666" classname="com.netease.vstore.test.cancelorder.CancelUnshipedOrder"/>
  <testcase name="ChangeProvince" time="1.708" classname="com.netease.vstore.test.cancelorder.CancelUnshipedOrder"/>
</testsuite> <!-- com.netease.vstore.test.cancelorder.CancelUnshipedOrder -->
